<?xml version="1.0"?>
<robot name="rm_gimbal">

  <!-- 根链接和大云台 -->
  <link name="odom"/>
  <link name="gimbal_big_link"/>

  <joint name="gimbal_joint" type="fixed">
    <origin xyz="0 0 0" rpy="0 0 0"/>
    <parent link="odom"/>
    <child link="gimbal_big_link"/>
  </joint>

  <!-- 左云台：增加固定偏移层 -->
  <link name="gimbal_left_link_offset"/>
  <joint name="gimbal_left_offset_joint" type="fixed">
    <origin xyz="0.04229 0.20951 0.15318" rpy="0 0 0"/>
    <parent link="gimbal_big_link"/>
    <child link="gimbal_left_link_offset"/>
  </joint>

  <link name="gimbal_left_link"/>
  <joint name="gimbal_big_to_gimbal_left_joint" type="continuous">
    <origin xyz="0 0 0" rpy="0 0 0"/>
    <parent link="gimbal_left_link_offset"/>
    <child link="gimbal_left_link"/>
    <axis xyz="0 0 1"/>
  </joint>

  <!-- 右云台：增加固定偏移层 -->
  <link name="gimbal_right_link_offset"/>
  <joint name="gimbal_right_offset_joint" type="fixed">
    <origin xyz="0.03382 -0.20951 0.15527" rpy="0 0 0"/>
    <parent link="gimbal_big_link"/>
    <child link="gimbal_right_link_offset"/>
  </joint>

  <link name="gimbal_right_link"/>
  <joint name="gimbal_big_to_gimbal_right_joint" type="continuous">
    <origin xyz="0 0 0" rpy="0 0 0"/>
    <parent link="gimbal_right_link_offset"/>
    <child link="gimbal_right_link"/>
    <axis xyz="0 0 1"/>
  </joint>

  <!-- 左摄像头链 -->
  <link name="left_camera_link"/>
  <joint name="left_camera_joint" type="fixed">
    <origin xyz="0.09733 0 0.01" rpy="0 0 0"/>
    <parent link="gimbal_left_link"/>
    <child link="left_camera_link"/>
  </joint>

  <link name="left_camera_optical_frame"/>
  <joint name="left_camera_optical_joint" type="fixed">
    <origin xyz="0.0 0 0.0" rpy="-1.5708 0 -1.5708"/>
    <parent link="left_camera_link"/>
    <child link="left_camera_optical_frame"/>
  </joint>

  <!-- 右摄像头链 -->
  <link name="right_camera_link"/>
  <joint name="right_camera_joint" type="fixed">
    <origin xyz="0.09733 0 0.01" rpy="0 0 0"/>
    <parent link="gimbal_right_link"/>
    <child link="right_camera_link"/>
  </joint>

  <link name="right_camera_optical_frame"/>
  <joint name="right_camera_optical_joint" type="fixed">
    <origin xyz="0.0 0 0.0" rpy="-1.5708 0 -1.5708"/>
    <parent link="right_camera_link"/>
    <child link="right_camera_optical_frame"/>
  </joint>

</robot>
